import { execute } from './Get';

describe('Get action', () => {
	it('should call helpers.requestWithAuthentication and return correct data (happy path)', async () => {
		const mockThis = {
			getCredentials: async () => ({ url: 'https://fake.api' }),
			helpers: {
				requestWithAuthentication: {
					call: jest.fn().mockResolvedValue({ id: '1', name: 'John Doe' }),
				},
			},
			getNodeParameter: (name: string, i: number) => {
				if (name === 'id') return '1';
				return undefined;
			},
			continueOnFail: () => false,
		} as any;
		const items = [{ json: {} }];
		const result = await execute.call(mockThis, items);
		expect(mockThis.helpers.requestWithAuthentication.call).toHaveBeenCalledWith(
			mockThis,
			'hipeApi',
			expect.objectContaining({
				method: 'GET',
				url: 'https://fake.api/api/users/1',
				json: true,
			}),
		);
		expect(result[0].json).toEqual({ id: '1', name: 'John Doe' });
	});

	it('should handle errors and push error object when continueOnFail is true (edge case)', async () => {
		const mockThis = {
			getCredentials: async () => ({ url: 'https://fake.api' }),
			helpers: {
				requestWithAuthentication: {
					call: jest.fn().mockRejectedValue(new Error('fail!')),
				},
			},
			getNodeParameter: (name: string, i: number) => '1',
			continueOnFail: () => true,
		} as any;
		const items = [{ json: {} }];
		const result = await execute.call(mockThis, items);
		expect(result[0].json).toEqual({ error: 'fail!' });
	});
});
